[2021-07-21 19:43:03,536] {taskinstance.py:896} INFO - Dependencies all met for <TaskInstance: scrape_nasdaq_ftp.nasdaq_symbols_process_files 2021-07-20T00:00:00+00:00 [queued]>
[2021-07-21 19:43:03,538] {taskinstance.py:896} INFO - Dependencies all met for <TaskInstance: scrape_nasdaq_ftp.nasdaq_symbols_process_files 2021-07-20T00:00:00+00:00 [queued]>
[2021-07-21 19:43:03,538] {taskinstance.py:1087} INFO - 
--------------------------------------------------------------------------------
[2021-07-21 19:43:03,538] {taskinstance.py:1088} INFO - Starting attempt 1 of 1
[2021-07-21 19:43:03,538] {taskinstance.py:1089} INFO - 
--------------------------------------------------------------------------------
[2021-07-21 19:43:03,550] {taskinstance.py:1107} INFO - Executing <Task(PythonOperator): nasdaq_symbols_process_files> on 2021-07-20T00:00:00+00:00
[2021-07-21 19:43:03,551] {standard_task_runner.py:52} INFO - Started process 192 to run task
[2021-07-21 19:43:03,553] {standard_task_runner.py:76} INFO - Running: ['airflow', 'tasks', 'run', 'scrape_nasdaq_ftp', 'nasdaq_symbols_process_files', '2021-07-20T00:00:00+00:00', '--job-id', '59', '--pool', 'default_pool', '--raw', '--subdir', 'DAGS_FOLDER/nasdaq_dag.py', '--cfg-path', '/tmp/tmpotegzu3y', '--error-file', '/tmp/tmptt1o7l5n']
[2021-07-21 19:43:03,553] {standard_task_runner.py:77} INFO - Job 59: Subtask nasdaq_symbols_process_files
[2021-07-21 19:43:03,571] {logging_mixin.py:104} INFO - Running <TaskInstance: scrape_nasdaq_ftp.nasdaq_symbols_process_files 2021-07-20T00:00:00+00:00 [running]> on host DESKTOP-4B4VMOV.localdomain
[2021-07-21 19:43:03,603] {taskinstance.py:1300} INFO - Exporting the following env vars:
AIRFLOW_CTX_DAG_OWNER=airflow
AIRFLOW_CTX_DAG_ID=scrape_nasdaq_ftp
AIRFLOW_CTX_TASK_ID=nasdaq_symbols_process_files
AIRFLOW_CTX_EXECUTION_DATE=2021-07-20T00:00:00+00:00
AIRFLOW_CTX_DAG_RUN_ID=scheduled__2021-07-20T00:00:00+00:00
[2021-07-21 19:43:03,603] {taskinstance.py:1501} ERROR - Task failed with exception
Traceback (most recent call last):
  File "/home/yaysh/anaconda3/envs/airflow/lib/python3.8/site-packages/airflow/models/taskinstance.py", line 1157, in _run_raw_task
    self._prepare_and_execute_task_with_callbacks(context, task)
  File "/home/yaysh/anaconda3/envs/airflow/lib/python3.8/site-packages/airflow/models/taskinstance.py", line 1331, in _prepare_and_execute_task_with_callbacks
    result = self._execute_task(context, task_copy)
  File "/home/yaysh/anaconda3/envs/airflow/lib/python3.8/site-packages/airflow/models/taskinstance.py", line 1361, in _execute_task
    result = task_copy.execute(context=context)
  File "/home/yaysh/anaconda3/envs/airflow/lib/python3.8/site-packages/airflow/operators/python.py", line 150, in execute
    return_value = self.execute_callable()
  File "/home/yaysh/anaconda3/envs/airflow/lib/python3.8/site-packages/airflow/operators/python.py", line 161, in execute_callable
    return self.python_callable(*self.op_args, **self.op_kwargs)
  File "/home/yaysh/airflow/dags/nasdaq_dag.py", line 38, in handle_nasdaq_symbols_file
    nasdaq_symbol_file_processor = NasdaqSymbolFileProcessor(basepath, db_host, db_db, db_username, db_password, db_port)
  File "/home/yaysh/airflow/dags/NasdaqScrapeScripts/nasdaq_symbol_file_processor.py", line 13, in __init__
    self.db_handler = NasdaqSymbolFileProcessorDatabaseHandler(DB_HOST, DB_DB, DB_USERNAME, DB_PASSWORD, DB_PORT)
  File "/home/yaysh/airflow/dags/NasdaqScrapeScripts/nasdaq_symbol_file_processor_db.py", line 12, in __init__
    self.createDatabaseIfDoesntExist()
  File "/home/yaysh/airflow/dags/NasdaqScrapeScripts/nasdaq_symbol_file_processor_db.py", line 42, in createDatabaseIfDoesntExist
    conn = self.getConnection()
  File "/home/yaysh/airflow/dags/NasdaqScrapeScripts/nasdaq_symbol_file_processor_db.py", line 16, in getConnection
    return psycopg2.connect(
  File "/home/yaysh/anaconda3/envs/airflow/lib/python3.8/site-packages/psycopg2/__init__.py", line 122, in connect
    conn = _connect(dsn, connection_factory=connection_factory, **kwasync)
psycopg2.OperationalError: could not connect to server: Connection refused
	Is the server running on host "localhost" (127.0.0.1) and accepting
	TCP/IP connections on port 5432?

[2021-07-21 19:43:03,606] {taskinstance.py:1544} INFO - Marking task as FAILED. dag_id=scrape_nasdaq_ftp, task_id=nasdaq_symbols_process_files, execution_date=20210720T000000, start_date=20210721T174303, end_date=20210721T174303
[2021-07-21 19:43:03,644] {local_task_job.py:149} INFO - Task exited with return code 1
